Workbook

Sheet employee
A1: Emp_ID | B1: FirstName | C1: LastName | D1: Gender | E1: Age | F1: Contact_Add | G1: Emp_Email | H1: Emp_Pass | I1: Job_ID
A2: 1 | B2: John | C2: Doe | D2: M | E2: 30 | F2: 123 Elm St, NY | G2: john.doe@example.com | H2: password123 | I2: 1
A3: 2 | B3: Jane | C3: Smith | D3: F | E3: 28 | F3: 456 Maple Ave, CA | G3: jane.smith@example.com | H3: password123 | I3: 2
A4: 3 | B4: Alice | C4: Brown | D4: F | E4: 35 | F4: 789 Oak St, TX | G4: alice.brown@example.com | H4: password123 | I4: 3
A5: 4 | B5: Bob | C5: Johnson | D5: M | E5: 40 | F5: 101 Pine St, FL | G5: bob.johnson@example.com | H5: password123 | I5: 4
A6: 5 | B6: Charlie | C6: Williams | D6: M | E6: 33 | F6: 202 Birch Rd, IL | G6: charlie.williams@example.com | H6: password123 | I6: 5
A7: 6 | B7: Dave | C7: Miller | D7: M | E7: 29 | F7: 303 Cedar Blvd, NY | G7: dave.miller@example.com | H7: password123 | I7: 6
A8: 7 | B8: Eve | C8: Davis | D8: F | E8: 25 | F8: 404 Maple Dr, TX | G8: eve.davis@example.com | H8: password123 | I8: 7
A9: 8 | B9: Frank | C9: Wilson | D9: M | E9: 38 | F9: 505 Pine Ave, FL | G9: frank.wilson@example.com | H9: password123 | I9: 8
A10: 9 | B10: Grace | C10: Moore | D10: F | E10: 45 | F10: 606 Oak Blvd, CA | G10: grace.moore@example.com | H10: password123 | I10: 9
A11: 10 | B11: Harry | C11: Taylor | D11: M | E11: 50 | F11: 707 Elm Rd, NY | G11: harry.taylor@example.com | H11: password123 | I11: 10
A12: 11 | B12: Irene | C12: Anderson | D12: F | E12: 32 | F12: 808 Maple St, FL | G12: irene.anderson@example.com | H12: password123 | I12: 11
A13: 12 | B13: Jack | C13: Thomas | D13: M | E13: 34 | F13: 909 Pine Rd, TX | G13: jack.thomas@example.com | H13: password123 | I13: 12
... A61: 60 | B61: Fiona | C61: Jackson | D61: F | E61: 30 | F61: 5757 Pine Blvd, TX | G61: fiona.jackson@example.com | H61: password123 | I61: 60

Sheet jobdepartment
A1: Job_ID | B1: JobDept | C1: Name | D1: Description | E1: SalaryRange
A2: 1 | B2: Operations | C2: Operations Engineer | D2: Responsible for engineer duties in the operations department. | E2: $70889 - $91502
A3: 2 | B3: Finance | C3: Finance Consultant | D3: Responsible for consultant duties in the finance department. | E3: $45757 - $102274
A4: 3 | B4: IT | C4: IT Coordinator | D4: Responsible for coordinator duties in the IT department. | E4: $32637 - $118326
A5: 4 | B5: Marketing | C5: Marketing Engineer | D5: Responsible for engineer duties in the marketing department. | E5: $48936 - $145464
A6: 5 | B6: Finance | C6: Finance Specialist | D6: Responsible for specialist duties in the finance department. | E6: $67562 - $99403
A7: 6 | B7: Engineering | C7: Engineering Executive | D7: Responsible for executive duties in the engineering department. | E7: $66000 - $125000
A8: 7 | B8: Sales | C8: Sales Manager | D8: Responsible for managing the sales department. | E8: $75000 - $130000
A9: 8 | B9: IT | C9: IT Analyst | D9: Responsible for analyzing IT systems in the IT department. | E9: $48000 - $92000
A10: 9 | B10: HR | C10: HR Manager | D10: Responsible for managing the human resources department. | E10: $68000 - $105000
A11: 10 | B11: Operations | C11: Operations Specialist | D11: Responsible for specialist duties in the operations department. | E11: $54000 - $90000
A12: 11 | B12: Marketing | C12: Marketing Coordinator | D12: Responsible for coordinating marketing campaigns. | E12: $55000 - $95000
A13: 12 | B13: Legal | C13: Legal Advisor | D13: Responsible for advising on legal matters in the organization. | E13: $95000 - $150000
... A61: 60 | B61: IT | C61: IT Manager | D61: Responsible for managing IT infrastructure and team. | E61: $120000 - $180000

Sheet salarybonus
A1: Salary_ID | B1: Job_ID | C1: Amount | D1: Annual | E1: Bonus
A2: 1 | B2: 1 | C2: 45000 | D2: 540000 | E2: 5000
A3: 2 | B3: 2 | C3: 55000 | D3: 660000 | E3: 7000
A4: 3 | B4: 3 | C4: 40000 | D4: 480000 | E4: 4000
A5: 4 | B5: 4 | C5: 48000 | D5: 576000 | E5: 6000
A6: 5 | B6: 5 | C6: 47000 | D6: 564000 | E6: 4500
A7: 6 | B7: 6 | C7: 65000 | D7: 780000 | E7: 10000
A8: 7 | B8: 7 | C8: 80000 | D8: 960000 | E8: 12000
A9: 8 | B9: 8 | C9: 42000 | D9: 504000 | E9: 3500
A10: 9 | B10: 9 | C10: 55000 | D10: 660000 | E10: 7000
A11: 10 | B11: 10 | C11: 48000 | D11: 576000 | E11: 5500
A12: 11 | B12: 11 | C12: 52000 | D12: 624000 | E12: 6000
A13: 12 | B13: 12 | C13: 90000 | D13: 1080000 | E13: 15000
... A61: 60 | B61: 60 | C61: 70000 | D61: 840000 | E61: 10000

Sheet payroll
A1: Payroll_ID | B1: Emp_ID | C1: Job_ID | D1: Salary_ID | E1: Leave_ID | F1: Date | G1: Report | H1: Total_Amount
A2: 1 | B2: 1 | C2: 1 | D2: 1 | E2: 1 | F2: 45412 | G2: April Payroll | H2: 40500
A3: 2 | B3: 2 | C3: 2 | D3: 2 | E3: 2 | F3: 45412 | G3: April Payroll | H3: 45500
A4: 3 | B4: 3 | C4: 3 | D4: 3 | E4: 3 | F4: 45412 | G4: April Payroll | H4: 39500
A5: 4 | B5: 4 | C5: 4 | D5: 4 | E5: 4 | F5: 45412 | G5: April Payroll | H5: 43500
A6: 5 | B6: 5 | C6: 5 | D6: 5 | E6: 5 | F6: 45412 | G6: April Payroll | H6: 38500
A7: 6 | B7: 6 | C7: 6 | D7: 6 | E7: 6 | F7: 45412 | G7: April Payroll | H7: 42500
A8: 7 | B8: 7 | C8: 7 | D8: 7 | E8: 7 | F8: 45412 | G8: April Payroll | H8: 44500
A9: 8 | B9: 8 | C9: 8 | D9: 8 | E9: 8 | F9: 45412 | G9: April Payroll | H9: 45500
A10: 9 | B10: 9 | C10: 9 | D10: 9 | E10: 9 | F10: 45412 | G10: April Payroll | H10: 40500
A11: 10 | B11: 10 | C11: 10 | D11: 10 | E11: 10 | F11: 45412 | G11: April Payroll | H11: 38500
A12: 11 | B12: 11 | C12: 11 | D12: 11 | E12: 11 | F12: 45412 | G12: April Payroll | H12: 49500
A13: 12 | B13: 12 | C13: 12 | D13: 12 | E13: 12 | F13: 45412 | G13: April Payroll | H13: 51500
... A61: 60 | B61: 60 | C61: 60 | D61: 60 | E61: 60 | F61: 45412 | G61: April Payroll | H61: 47500

Sheet Department Headcount
A1: Department Headcount
A3: Row Labels | B3: Count of Emp_ID
A4: Engineering | B4: 7
A5: Finance | B5: 9
A6: HR | B6: 7
A7: IT | B7: 9
A8: Legal | B8: 5
A9: Marketing | B9: 8
A10: Operations | B10: 8
A11: Sales | B11: 7
A12: (blank)
A13: Grand Total | B13: 60

Sheet Department Salary Cost
A1: Department Salary Cost
A3: Row Labels | B3: Sum of Salary
A4: Engineering | B4: 568000
A5: Finance | B5: 651000
A6: HR | B6: 438000
A7: IT | B7: 638000
A8: Legal | B8: 423000
A9: Marketing | B9: 525000
A10: Operations | B10: 550000
A11: Sales | B11: 528000
A12: (blank)
A13: Grand Total | B13: 4321000

Sheet Employee Payroll Summary
A1: Employee Payroll Summary
A3: Row Labels | B3: Sum of Salary | C3: Sum of Bonus | D3: Sum of Payroll
A4: Engineering | B4: 568000 | C4: 88000 | D4: 321500
A5: 6 | B5: 65000 | C5: 10000 | D5: 42500
A6: 15 | B6: 55000 | C6: 6000 | D6: 47500
A7: 23 | B7: 85000 | C7: 12000 | D7: 45500
A8: 31 | B8: 115000 | C8: 18000 | D8: 41500
A9: 38 | B9: 160000 | C9: 33000 | D9: 47500
A10: 45 | B10: 42000 | C10: 3500 | D10: 47500
A11: 53 | B11: 46000 | C11: 5500 | D11: 49500
A12: Finance | B12: 651000 | C12: 96000 | D12: 420500
A13: 2 | B13: 55000 | C13: 7000 | D13: 45500
A14: 5 | B14: 47000 | C14: 4500 | D14: 38500
A15: 13 | B15: 60000 | C15: 8000 | D15: 50500
A16: 21 | B16: 95000 | C16: 15000 | D16: 46500
A17: 30 | B17: 105000 | C17: 15000 | D17: 50500
A18: 37 | B18: 170000 | C18: 35000 | D18: 44500
A19: 43 | B19: 32000 | C19: 3000 | D19: 49500
A20: 51 | B20: 42000 | C20: 4000 | D20: 50500
A21: 59 | B21: 45000 | C21: 4500 | D21: 44500
A22: HR | B22: 438000 | C22: 57200 | D22: 319500
A23: 9 | B23: 55000 | C23: 7000 | D23: 40500
A24: 18 | B24: 60000 | C24: 7500 | D24: 51500
A25: 25 | B25: 72000 | C25: 8500 | D25: 45500
A26: 33 | B26: 120000 | C26: 20000 | D26: 49500
A27: 40 | B27: 50000 | C27: 6000 | D27: 46500
A28: 48 | B28: 34000 | C28: 3200 | D28: 43500
A29: 56 | B29: 47000 | C29: 5000 | D29: 42500
A30: IT | B30: 638000 | C30: 94000 | D30: 413500
A31: 3 | B31: 40000 | C31: 4000 | D31: 39500
A32: 8 | B32: 42000 | C32: 3500 | D32: 45500
A33: 14 | B33: 38000 | C33: 3000 | D33: 48500
A34: 22 | B34: 105000 | C34: 18000 | D34: 47500
A35: 28 | B35: 120000 | C35: 20000 | D35: 49500
A36: 36 | B36: 150000 | C36: 28000 | D36: 43500
A37: 44 | B37: 38000 | C37: 4000 | D37: 45500
A38: 52 | B38: 35000 | C38: 3500 | D38: 46500
A39: 60 | B39: 70000 | C39: 10000 | D39: 47500
A40: Legal | B40: 423000 | C40: 66500 | D40: 238500
A41: 12 | B41: 90000 | C41: 15000 | D41: 51500
...

Sheet Master_Data
A1: Emp_ID | B1: FirstName | C1: LastName | D1: Gender | E1: Age | F1: Contact_Add | G1: Emp_Email | H1: Emp_Pass | I1: Job_ID | J1: Department | K1: Salary | L1: Bonus | M1: Payroll
A2: 1 | B2: John | C2: Doe | D2: M | E2: 30 | F2: 123 Elm St, NY | G2: john.doe@example.com | H2: password123 | I2: 1 | J2: =VLOOKUP(I2, jobdepartment!$A:$B, 2, FALSE) -> Operations | K2: =VLOOKUP(I2,salarybonus!$B:$C, 2, FALSE) -> 45000 | L2: =VLOOKUP(I2, salarybonus!$B:$E,4,FALSE) -> 5000 | M2: =VLOOKUP(A2, payroll!$B:$H, 7, FALSE) -> 40500
A3: 2 | B3: Jane | C3: Smith | D3: F | E3: 28 | F3: 456 Maple Ave, CA | G3: jane.smith@example.com | H3: password123 | I3: 2 | J3: =VLOOKUP(I3, jobdepartment!$A:$B, 2, FALSE) -> Finance | K3: =VLOOKUP(I3,salarybonus!$B:$C, 2, FALSE) -> 55000 | L3: =VLOOKUP(I3, salarybonus!$B:$E,4,FALSE) -> 7000 | M3: =VLOOKUP(A3, payroll!$B:$H, 7, FALSE) -> 45500
A4: 3 | B4: Alice | C4: Brown | D4: F | E4: 35 | F4: 789 Oak St, TX | G4: alice.brown@example.com | H4: password123 | I4: 3 | J4: =VLOOKUP(I4, jobdepartment!$A:$B, 2, FALSE) -> IT | K4: =VLOOKUP(I4,salarybonus!$B:$C, 2, FALSE) -> 40000 | L4: =VLOOKUP(I4, salarybonus!$B:$E,4,FALSE) -> 4000 | M4: =VLOOKUP(A4, payroll!$B:$H, 7, FALSE) -> 39500
A5: 4 | B5: Bob | C5: Johnson | D5: M | E5: 40 | F5: 101 Pine St, FL | G5: bob.johnson@example.com | H5: password123 | I5: 4 | J5: =VLOOKUP(I5, jobdepartment!$A:$B, 2, FALSE) -> Marketing | K5: =VLOOKUP(I5,salarybonus!$B:$C, 2, FALSE) -> 48000 | L5: =VLOOKUP(I5, salarybonus!$B:$E,4,FALSE) -> 6000 | M5: =VLOOKUP(A5, payroll!$B:$H, 7, FALSE) -> 43500
A6: 5 | B6: Charlie | C6: Williams | D6: M | E6: 33 | F6: 202 Birch Rd, IL | G6: charlie.williams@example.com | H6: password123 | I6: 5 | J6: =VLOOKUP(I6, jobdepartment!$A:$B, 2, FALSE) -> Finance | K6: =VLOOKUP(I6,salarybonus!$B:$C, 2, FALSE) -> 47000 | L6: =VLOOKUP(I6, salarybonus!$B:$E,4,FALSE) -> 4500 | M6: =VLOOKUP(A6, payroll!$B:$H, 7, FALSE) -> 38500
A7: 6 | B7: Dave | C7: Miller | D7: M | E7: 29 | F7: 303 Cedar Blvd, NY | G7: dave.miller@example.com | H7: password123 | I7: 6 | J7: =VLOOKUP(I7, jobdepartment!$A:$B, 2, FALSE) -> Engineering | K7: =VLOOKUP(I7,salarybonus!$B:$C, 2, FALSE) -> 65000 | L7: =VLOOKUP(I7, salarybonus!$B:$E,4,FALSE) -> 10000 | M7: =VLOOKUP(A7, payroll!$B:$H, 7, FALSE) -> 42500
A8: 7 | B8: Eve | C8: Davis | D8: F | E8: 25 | F8: 404 Maple Dr, TX | G8: eve.davis@example.com | H8: password123 | I8: 7 | J8: =VLOOKUP(I8, jobdepartment!$A:$B, 2, FALSE) -> Sales | K8: =VLOOKUP(I8,salarybonus!$B:$C, 2, FALSE) -> 80000 | L8: =VLOOKUP(I8, salarybonus!$B:$E,4,FALSE) -> 12000 | M8: =VLOOKUP(A8, payroll!$B:$H, 7, FALSE) -> 44500
A9: 8 | B9: Frank | C9: Wilson | D9: M | E9: 38 | F9: 505 Pine Ave, FL | G9: frank.wilson@example.com | H9: password123 | I9: 8 | J9: =VLOOKUP(I9, jobdepartment!$A:$B, 2, FALSE) -> IT | K9: =VLOOKUP(I9,salarybonus!$B:$C, 2, FALSE) -> 42000 | L9: =VLOOKUP(I9, salarybonus!$B:$E,4,FALSE) -> 3500 | M9: =VLOOKUP(A9, payroll!$B:$H, 7, FALSE) -> 45500
A10: 9 | B10: Grace | C10: Moore | D10: F | E10: 45 | F10: 606 Oak Blvd, CA | G10: grace.moore@example.com | H10: password123 | I10: 9 | J10: =VLOOKUP(I10, jobdepartment!$A:$B, 2, FALSE) -> HR | K10: =VLOOKUP(I10,salarybonus!$B:$C, 2, FALSE) -> 55000 | L10: =VLOOKUP(I10, salarybonus!$B:$E,4,FALSE) -> 7000 | M10: =VLOOKUP(A10, payroll!$B:$H, 7, FALSE) -> 40500
A11: 10 | B11: Harry | C11: Taylor | D11: M | E11: 50 | F11: 707 Elm Rd, NY | G11: harry.taylor@example.com | H11: password123 | I11: 10 | J11: =VLOOKUP(I11, jobdepartment!$A:$B, 2, FALSE) -> Operations | K11: =VLOOKUP(I11,salarybonus!$B:$C, 2, FALSE) -> 48000 | L11: =VLOOKUP(I11, salarybonus!$B:$E,4,FALSE) -> 5500 | M11: =VLOOKUP(A11, payroll!$B:$H, 7, FALSE) -> 38500
A12: 11 | B12: Irene | C12: Anderson | D12: F | E12: 32 | F12: 808 Maple St, FL | G12: irene.anderson@example.com | H12: password123 | I12: 11 | J12: =VLOOKUP(I12, jobdepartment!$A:$B, 2, FALSE) -> Marketing | K12: =VLOOKUP(I12,salarybonus!$B:$C, 2, FALSE) -> 52000 | L12: =VLOOKUP(I12, salarybonus!$B:$E,4,FALSE) -> 6000 | M12: =VLOOKUP(A12, payroll!$B:$H, 7, FALSE) -> 49500
A13: 12 | B13: Jack | C13: Thomas | D13: M | E13: 34 | F13: 909 Pine Rd, TX | G13: jack.thomas@example.com | H13: password123 | I13: 12 | J13: =VLOOKUP(I13, jobdepartment!$A:$B, 2, FALSE) -> Legal | K13: =VLOOKUP(I13,salarybonus!$B:$C, 2, FALSE) -> 90000 | L13: =VLOOKUP(I13, salarybonus!$B:$E,4,FALSE) -> 15000 | M13: =VLOOKUP(A13, payroll!$B:$H, 7, FALSE) -> 51500
... A61: 60 | B61: Fiona | C61: Jackson | D61: F | E61: 30 | F61: 5757 Pine Blvd, TX | G61: fiona.jackson@example.com | H61: password123 | I61: 60 | J61: =VLOOKUP(I61, jobdepartment!$A:$B, 2, FALSE) -> IT | K61: =VLOOKUP(I61,salarybonus!$B:$C, 2, FALSE) -> 70000 | L61: =VLOOKUP(I61, salarybonus!$B:$E,4,FALSE) -> 10000 | M61: =VLOOKUP(A61, payroll!$B:$H, 7, FALSE) -> 47500
